{
  "file_name": "benchcalcu:rough.pl",
  "run_index": 4,
  "Validity_form": "ERROR",
  "Validity_result": "ERROR",
  "running_time": "None",
  "iter_count": "None",
  "process_time": 669.9400181770325,
  "final_result": "Agent execution error: DeepSeek API returned an invalid response. Please check the API status and try again.: line 10 column 1 (char 9)",
  "final_report": "Stack trace: Traceback (most recent call last):\n  File \"/Users/zhenzhili/miniforge3/envs/langda/lib/python3.11/site-packages/langchain_deepseek/chat_models.py\", line 296, in _generate\n    return super()._generate(\n           ^^^^^^^^^^^^^^^^^^\n  File \"/Users/zhenzhili/miniforge3/envs/langda/lib/python3.11/site-packages/langchain_openai/chat_models/base.py\", line 955, in _generate\n    response = self.client.create(**payload)\n               ^^^^^^^^^^^^^^^^^^^^^^^^^^^^^\n  File \"/Users/zhenzhili/miniforge3/envs/langda/lib/python3.11/site-packages/openai/_utils/_utils.py\", line 279, in wrapper\n    return func(*args, **kwargs)\n           ^^^^^^^^^^^^^^^^^^^^^\n  File \"/Users/zhenzhili/miniforge3/envs/langda/lib/python3.11/site-packages/openai/resources/chat/completions/completions.py\", line 914, in create\n    return self._post(\n           ^^^^^^^^^^^\n  File \"/Users/zhenzhili/miniforge3/envs/langda/lib/python3.11/site-packages/openai/_base_client.py\", line 1242, in post\n    return cast(ResponseT, self.request(cast_to, opts, stream=stream, stream_cls=stream_cls))\n                           ^^^^^^^^^^^^^^^^^^^^^^^^^^^^^^^^^^^^^^^^^^^^^^^^^^^^^^^^^^^^^^^^^\n  File \"/Users/zhenzhili/miniforge3/envs/langda/lib/python3.11/site-packages/openai/_base_client.py\", line 919, in request\n    return self._request(\n           ^^^^^^^^^^^^^^\n  File \"/Users/zhenzhili/miniforge3/envs/langda/lib/python3.11/site-packages/openai/_base_client.py\", line 1025, in _request\n    return self._process_response(\n           ^^^^^^^^^^^^^^^^^^^^^^^\n  File \"/Users/zhenzhili/miniforge3/envs/langda/lib/python3.11/site-packages/openai/_base_client.py\", line 1124, in _process_response\n    return api_response.parse()\n           ^^^^^^^^^^^^^^^^^^^^\n  File \"/Users/zhenzhili/miniforge3/envs/langda/lib/python3.11/site-packages/openai/_response.py\", line 323, in parse\n    parsed = self._parse(to=to)\n             ^^^^^^^^^^^^^^^^^^\n  File \"/Users/zhenzhili/miniforge3/envs/langda/lib/python3.11/site-packages/openai/_response.py\", line 265, in _parse\n    data = response.json()\n           ^^^^^^^^^^^^^^^\n  File \"/Users/zhenzhili/miniforge3/envs/langda/lib/python3.11/site-packages/httpx/_models.py\", line 832, in json\n    return jsonlib.loads(self.content, **kwargs)\n           ^^^^^^^^^^^^^^^^^^^^^^^^^^^^^^^^^^^^^\n  File \"/Users/zhenzhili/miniforge3/envs/langda/lib/python3.11/json/__init__.py\", line 346, in loads\n    return _default_decoder.decode(s)\n           ^^^^^^^^^^^^^^^^^^^^^^^^^^\n  File \"/Users/zhenzhili/miniforge3/envs/langda/lib/python3.11/json/decoder.py\", line 337, in decode\n    obj, end = self.raw_decode(s, idx=_w(s, 0).end())\n               ^^^^^^^^^^^^^^^^^^^^^^^^^^^^^^^^^^^^^^\n  File \"/Users/zhenzhili/miniforge3/envs/langda/lib/python3.11/json/decoder.py\", line 355, in raw_decode\n    raise JSONDecodeError(\"Expecting value\", s, err.value) from None\njson.decoder.JSONDecodeError: Expecting value: line 10 column 1 (char 9)\n\nThe above exception was the direct cause of the following exception:\n\nTraceback (most recent call last):\n  File \"/Users/zhenzhili/MASTERTHESIS/#Expert_System_Design/examples/LANGDA/#drone_with_dpl_in_langgraph_v6.4/main_test_multi.py\", line 113, in process_all_prompt_files_json\n    result = with_timeout(agent.call_langda_workflow, file_name, timeout)\n             ^^^^^^^^^^^^^^^^^^^^^^^^^^^^^^^^^^^^^^^^^^^^^^^^^^^^^^^^^^^^\n  File \"/Users/zhenzhili/MASTERTHESIS/#Expert_System_Design/examples/LANGDA/#drone_with_dpl_in_langgraph_v6.4/utils/test_tools.py\", line 23, in with_timeout\n    result = func(*args, **kwargs)\n             ^^^^^^^^^^^^^^^^^^^^^\n  File \"/Users/zhenzhili/MASTERTHESIS/#Expert_System_Design/examples/LANGDA/#drone_with_dpl_in_langgraph_v6.4/agent/langda_agent.py\", line 128, in call_langda_workflow\n    self.state = langda_agent.invoke(self.state, config=self.state[\"config\"])\n                 ^^^^^^^^^^^^^^^^^^^^^^^^^^^^^^^^^^^^^^^^^^^^^^^^^^^^^^^^^^^^\n  File \"/Users/zhenzhili/miniforge3/envs/langda/lib/python3.11/site-packages/langgraph/pregel/__init__.py\", line 2683, in invoke\n    for chunk in self.stream(\n  File \"/Users/zhenzhili/miniforge3/envs/langda/lib/python3.11/site-packages/langgraph/pregel/__init__.py\", line 2331, in stream\n    for _ in runner.tick(\n  File \"/Users/zhenzhili/miniforge3/envs/langda/lib/python3.11/site-packages/langgraph/pregel/runner.py\", line 146, in tick\n    run_with_retry(\n  File \"/Users/zhenzhili/miniforge3/envs/langda/lib/python3.11/site-packages/langgraph/pregel/retry.py\", line 40, in run_with_retry\n    return task.proc.invoke(task.input, config)\n           ^^^^^^^^^^^^^^^^^^^^^^^^^^^^^^^^^^^^\n  File \"/Users/zhenzhili/miniforge3/envs/langda/lib/python3.11/site-packages/langgraph/utils/runnable.py\", line 606, in invoke\n    input = step.invoke(input, config, **kwargs)\n            ^^^^^^^^^^^^^^^^^^^^^^^^^^^^^^^^^^^^\n  File \"/Users/zhenzhili/miniforge3/envs/langda/lib/python3.11/site-packages/langgraph/utils/runnable.py\", line 371, in invoke\n    ret = context.run(self.func, *args, **kwargs)\n          ^^^^^^^^^^^^^^^^^^^^^^^^^^^^^^^^^^^^^^^\n  File \"/Users/zhenzhili/MASTERTHESIS/#Expert_System_Design/examples/LANGDA/#drone_with_dpl_in_langgraph_v6.4/agent/general_nodes.py\", line 117, in summary_node\n    final_result, _  = invoke_agent(\n                       ^^^^^^^^^^^^^\n  File \"/Users/zhenzhili/MASTERTHESIS/#Expert_System_Design/examples/LANGDA/#drone_with_dpl_in_langgraph_v6.4/utils/__init__.py\", line 55, in invoke_agent\n    return executor.invoke_simple_agent(prompt_type,input,config)\n           ^^^^^^^^^^^^^^^^^^^^^^^^^^^^^^^^^^^^^^^^^^^^^^^^^^^^^^\n  File \"/Users/zhenzhili/MASTERTHESIS/#Expert_System_Design/examples/LANGDA/#drone_with_dpl_in_langgraph_v6.4/utils/models.py\", line 192, in invoke_simple_agent\n    result = chain.invoke(input=input, config=config)\n             ^^^^^^^^^^^^^^^^^^^^^^^^^^^^^^^^^^^^^^^^\n  File \"/Users/zhenzhili/miniforge3/envs/langda/lib/python3.11/site-packages/langchain_core/runnables/base.py\", line 3034, in invoke\n    input = context.run(step.invoke, input, config)\n            ^^^^^^^^^^^^^^^^^^^^^^^^^^^^^^^^^^^^^^^\n  File \"/Users/zhenzhili/miniforge3/envs/langda/lib/python3.11/site-packages/langchain_core/language_models/chat_models.py\", line 370, in invoke\n    self.generate_prompt(\n  File \"/Users/zhenzhili/miniforge3/envs/langda/lib/python3.11/site-packages/langchain_core/language_models/chat_models.py\", line 947, in generate_prompt\n    return self.generate(prompt_messages, stop=stop, callbacks=callbacks, **kwargs)\n           ^^^^^^^^^^^^^^^^^^^^^^^^^^^^^^^^^^^^^^^^^^^^^^^^^^^^^^^^^^^^^^^^^^^^^^^^\n  File \"/Users/zhenzhili/miniforge3/envs/langda/lib/python3.11/site-packages/langchain_core/language_models/chat_models.py\", line 766, in generate\n    self._generate_with_cache(\n  File \"/Users/zhenzhili/miniforge3/envs/langda/lib/python3.11/site-packages/langchain_core/language_models/chat_models.py\", line 1012, in _generate_with_cache\n    result = self._generate(\n             ^^^^^^^^^^^^^^^\n  File \"/Users/zhenzhili/miniforge3/envs/langda/lib/python3.11/site-packages/langchain_deepseek/chat_models.py\", line 300, in _generate\n    raise JSONDecodeError(\njson.decoder.JSONDecodeError: DeepSeek API returned an invalid response. Please check the API status and try again.: line 10 column 1 (char 9)\nDuring task with name 'summary_node' and id '8ba9ff18-db8e-3064-6ff0-970f789cb2f0'\n"
}